<?xml version="1.0"?>
<robot name="cart_pole">
  <!-- ros_control plugin -->
  <gazebo>
    <plugin name="gazebo_ros_control" filename="libgazebo_ros_control.so">
      <robotNamespace>/cart_pole</robotNamespace>
      <robotSimType>gazebo_ros_control/DefaultRobotHWSim</robotSimType>
    </plugin>
  </gazebo>

    <material name="red">
        <color rgba="0.77 0.12 0.23 0.7"/>
    </material>

    <material name="gold">
        <color rgba="1 0.843 0 1"/>
    </material>


  <link name="world">
  </link>
                <!-- * * * Link Definitions * * * -->

  <joint name="dummy_joint" type="fixed">
    <parent link="world"/>
    <child link="dummy_link"/>
    <origin xyz="0 0 0.05"/>
  </joint>

<link name="dummy_link">
    
    <inertial>
      <mass value="0.1"/>
      <origin xyz="0 0 0"/>
      <inertia ixx="0.00001" ixy="0" ixz="0" iyy="0.00001" iyz="0" izz="0.00001"/>
    </inertial>

    <!-- <collision>
        <origin xyz="0 0 0" rpy="0 0 0"/>
        <geometry>
            <box size="0.001 0.001 0.001"/>
        </geometry>
    </collision>   -->

    <visual>
      <origin xyz="0 0 0" rpy="0 0 0" />
      <geometry>
        <box size="1 0.1 0.01"/>
      </geometry>
      <material name="red"/>
    </visual>
  
  </link>

    <gazebo reference="dummy_link">
    <kp>100000.0</kp>
    <kd>100000.0</kd>
    <mu1>0.2</mu1>
    <mu2>0.2</mu2>
    <material>Gazebo/Grey</material>
    </gazebo>

  <joint name="cart_joint" type="prismatic">
    <parent link="world"/>
    <child link="cart_link"/>
    <origin xyz="0 0 0.05"/>
    <axis xyz="1 0 0"/>
    <limit lower="-10" upper="10" effort="600" velocity="200"/>
  </joint>

<link name="cart_link">
    
    <inertial>
      <mass value="10"/>
      <origin xyz="0 0 0"/>
      <inertia ixx="0.08333" ixy="0" ixz="0" iyy="0.21667" iyz="0" izz="0.2833"/>
    </inertial>

    <collision>
        <origin xyz="0 0 0" rpy="0 0 0"/>
        <geometry>
            <box size="0.5 0.3 0.1"/>
        </geometry>
    </collision>  

    <visual>
      <origin xyz="0 0 0" rpy="0 0 0" />
      <geometry>
        <box size="0.5 0.3 0.1"/>
      </geometry>
      <material name="red"/>
    </visual>
  
  </link>

    <gazebo reference="cart_link">
    <kp>100000.0</kp>
    <kd>100000.0</kd>
    <mu1>0.2</mu1>
    <mu2>0.2</mu2>
    <material>Gazebo/Gold</material>
    </gazebo>

  <joint name="pole_joint" type="continuous">
    <parent link="cart_link"/>
    <child link="pole_link"/>
    <origin xyz="0 0 0.05" rpy="0 0.25 0"/>
    <axis xyz="0 1 0"/>
    <!-- <dynamics damping="0.05"/> -->
  </joint>

  <link name="pole_link">
    
    <inertial>
      <mass value="2"/>
      <origin xyz="0 0 0.5" rpy="0 0 0" />
      <inertia ixx="0.02" ixy="0" ixz="0" iyy="0.6667" iyz="0" izz="0.02"/>
    </inertial>

     <!-- <collision>
        <origin xyz="0 0 0.5" rpy="0 0 0"/>
        <geometry>
            <cylinder radius="0.019" length="0.9"/>
        </geometry>
    </collision>    -->

    <visual>
      <origin xyz="0 0 0.5" rpy="0 0 0" />
      <geometry>
        <cylinder radius="0.02" length="1"/>
      </geometry>
      <material name="gold"/>
    </visual>
  
  </link>

    <gazebo reference="pole_link">
    <kp>100000.0</kp>
    <kd>100000.0</kd>
    <mu1>0.2</mu1>
    <mu2>0.2</mu2>
    <material>Gazebo/Red</material>
    </gazebo>

    <!-- <gazebo>
    <plugin name="joint_state_publisher" filename="libgazebo_ros_joint_state_publisher.so">
        <jointName>cart_joint</jointName>
        <topicName>joint_states</topicName>
        <updateRate>50.0</updateRate>
    </plugin>
  </gazebo>  

  <gazebo>
    <plugin name="joint_state_publisher" filename="libgazebo_ros_joint_state_publisher.so">
        <jointName>pole_joint</jointName>
        <topicName>joint_states</topicName>
        <updateRate>50.0</updateRate>
    </plugin>
  </gazebo> -->



  <transmission name="tran1">
    <type>transmission_interface/SimpleTransmission</type>
    <joint name="cart_joint">
      <hardwareInterface>hardware_interface/EffortJointInterface</hardwareInterface>
    </joint>
    
    <actuator name="motor1">
      <hardwareInterface>hardware_interface/EffortJointInterface</hardwareInterface>
      <mechanicalReduction>1</mechanicalReduction>
    </actuator>
  </transmission>

<!-- The following is a dummy pole actuator. pole joint is unactuated but this is for state estimation purposes only -->
    <transmission name="tran2">
    <type>transmission_interface/SimpleTransmission</type>
    <joint name="pole_joint">
      <hardwareInterface>hardware_interface/EffortJointInterface</hardwareInterface>
    </joint>
    
    <actuator name="motor2">
      <hardwareInterface>hardware_interface/EffortJointInterface</hardwareInterface>
      <mechanicalReduction>1</mechanicalReduction>
    </actuator>
  </transmission>


</robot>
