<?xml version="1.0"?>
<robot name="cart_pole">

    <material name="red">
        <color rgba="0.77 0.12 0.23 0.7"/>
    </material>

    <material name="gold">
        <color rgba="1 0.843 0 1"/>
    </material>


  <link name="base_link">
  </link>
                <!-- * * * Link Definitions * * * -->

  <joint name="cart_joint" type="fixed">
    <parent link="base_link"/>
    <child link="cart_link"/>
    <origin xyz="0 0 0.05"/>
    <!-- <axis xyz="1 0 0"/> -->
    <!-- <limit lower="-5" upper="5" effort="10" velocity="1"/> -->
  </joint>

<link name="cart_link">
    
    <inertial>
      <mass value="1"/>
      <origin xyz="0 0 0"/>
      <inertia ixx="0.008333" ixy="0" ixz="0" iyy="0.021667" iyz="0" izz="0.02833"/>
    </inertial>

    <collision>
        <origin xyz="0 0 0" rpy="0 0 0"/>
        <geometry>
            <box size="0.5 0.3 0.1"/>
        </geometry>
    </collision>  

    <visual>
      <origin xyz="0 0 0" rpy="0 0 0" />
      <geometry>
        <box size="0.5 0.3 0.1"/>
      </geometry>
      <material name="red"/>
    </visual>
  
  </link>

    <gazebo reference="cart_link">
    <kp>100000.0</kp>
    <kd>100000.0</kd>
    <mu1>10.0</mu1>
    <mu2>10.0</mu2>
    <material>Gazebo/Grey</material>
    </gazebo>

  <joint name="pole_joint" type="continuous">
    <parent link="cart_link"/>
    <child link="pole_link"/>
    <origin xyz="0 0 0.05" rpy="0 0 0"/>
    <axis xyz="0 1 0"/>
  </joint>

  <link name="pole_link">
    
    <inertial>
      <mass value="0.1"/>
      <origin xyz="0 0 0.5" rpy="0 0 0" />
      <inertia ixx="0.001" ixy="0" ixz="0" iyy="0.03333" iyz="0" izz="0.001"/>
    </inertial>

     <!-- <collision>
        <origin xyz="0 0 0.5" rpy="0 0 0"/>
        <geometry>
            <cylinder radius="0.019" length="0.9"/>
        </geometry>
    </collision>    -->

    <visual>
      <origin xyz="0 0 0.5" rpy="0 0 0" />
      <geometry>
        <cylinder radius="0.02" length="1"/>
      </geometry>
      <material name="gold"/>
    </visual>
  
  </link>

    <gazebo reference="pole_link">
    <kp>100000.0</kp>
    <kd>100000.0</kd>
    <mu1>10.0</mu1>
    <mu2>10.0</mu2>
    <material>Gazebo/Blue</material>
    </gazebo>

</robot>
